Workbook

Sheet Sheet1
A1: 1
A2: Pucha Wholesaler LLC
A3: January 1-December 23, 2025
B5: Transaction date | C5: Transaction type | D5: Num | E5: Product/Service full name | F5: Memo/Description | G5: Quantity | H5: Rate | I5: Amount | J5: Balance
A6: Amazon
A7: Amazon | B7: 06/02/2025 | C7: Bill | E7: Display Strip | F7: Used for product displays at retail stores | G7: 8 | H7: 5.41 | I7: 43.28 | J7: 43.28
A8: Amazon | B8: 06/04/2025 | C8: Expense | E8: Display Strip | F8: AMAZON MKTPL*N647V 06-03 Amzn.com/bill WA 6953 DEBIT CARD PURCHASE | G8: 8 | H8: 5.41 | I8: 43.28 | J8: 86.56
A9: Total for Amazon | I9: =I7+I8 -> 86.56
A10: Arjo Vision Trading Company LLC
A11: Arjo Vision Trading Company LLC | B11: 03/19/2025 | C11: Bill | D11: 295 | E11: Volt yellow Guarana 16fl oz /15 | F11: Volt yellow Guarana lata 16fl oz /15 | G11: 15 | H11: 16.0226 | I11: 240.34 | J11: 240.34
A12: Total for Arjo Vision Trading Company LLC | I12: =I11 -> 240.34
A13: Belmont International Trading Corp
A14: Belmont International Trading Corp | B14: 04/28/2025 | C14: Bill | D14: 64308 | E14: Belmont Yuyo Marino FROZEN 2.2lb x 8 | F14: Belmont Yuyo Marino FROZEN 2.2lb x 8 / 1FP-36 | G14: 1 | H14: 54 | I14: 54 | J14: 54
A15: Belmont International Trading Corp | B15: 04/28/2025 | C15: Bill | D15: 64308 | E15: Belmont Chirimoya pulpa 14oz x 20 | F15: Belmont Chirimoya pulpa 14oz x 20 / 859174003153 | G15: 1 | H15: 48 | I15: 48 | J15: 102
A16: Belmont International Trading Corp | B16: 04/28/2025 | C16: Bill | D16: 64308 | E16: Belmont Aji Amarillo entero 1Lb x 18 FROZEN | F16: BELMONT - Belmont Aji Amarillo entero 1Lb x 18 bolsas FROZEN | G16: 6 | H16: 45 | I16: 270 | J16: 372
A17: Belmont International Trading Corp | B17: 04/28/2025 | C17: Bill | D17: 64308 | E17: Belmont Choclo desgranado 1Lb x 30 FROZEN | F17: BELMONT - Belmont Choclo desgranado 1Lb x 30 bolsas FROZEN / 1FP-08 | G17: 6 | H17: 72.5 | I17: 435 | J17: 807
A18: Belmont International Trading Corp | B18: 04/28/2025 | C18: Bill | D18: 64308 | E18: Belmont Aji Limo 14oz x 9 FROZEN | F18: BELMONT - Belmont Aji Limo 14oz x 9 bolsas FROZEN | G18: 1 | H18: 20.9 | I18: 20.9 | J18: 827.9
A19: Belmont International Trading Corp | B19: 04/28/2025 | C19: Bill | D19: 64308 | E19: Belmont Aji Amarillo pasta 8oz x 12 | F19: BELMONT - Belmont Aji Amarillo pasta 8oz x 12 frascos de vidrio / PA-02 | G19: 3 | H19: 23.5 | I19: 70.5 | J19: 898.4
A20: Belmont International Trading Corp | B20: 04/28/2025 | C20: Bill | D20: 64308 | E20: Belmont Aji Panca pasta 8oz x 12 | F20: BELMONT - Belmont Aji Panca pasta 8oz x 12 frascos de vidrio / PA-08 | G20: 2 | H20: 23.5 | I20: 47 | J20: 945.4
A21: Belmont International Trading Corp | B21: 04/28/2025 | C21: Bill | D21: 64308 | E21: AJINOSIYAO 500ml x 24 | F21: TA- PERU - CONDIMENT PRODUCTS - AJI NO Siyau- 24 / 500 ml - 00999 | G21: 1 | H21: 50.4 | I21: 50.4 | J21: 995.8
A22: Belmont International Trading Corp | B22: 04/28/2025 | C22: Bill | D22: 64308 | E22: Ajinomoto Bolsa 250gr x 60 | F22: TA- PERU - CONDIMENT PRODUCTS - MSG -AJINOMOTO- 60 / 250gr - 00995 | G22: 1 | H22: 90 | I22: 90 | J22: 1085.8
A23: Belmont International Trading Corp | B23: 04/28/2025 | C23: Bill | D23: 64308 | E23: Chocolate Cuzco con canela y clavo 4 x 12 | F23: Chocolate Cuzco con canela y clavo 4 x 12 | G23: 1 | H23: 30 | I23: 30 | J23: 1115.8
A24: Belmont International Trading Corp | B24: 04/28/2025 | C24: Bill | D24: 64308 | E24: Chocolate Cuzco regular 4 x 12 | F24: Chocolate Cuzco regular 4 x 12 / 859174003672 / AB-07 | G24: 1 | H24: 30 | I24: 30 | J24: 1145.8
A25: Belmont International Trading Corp | B25: 04/28/2025 | C25: Bill | D25: 64308 | E25: AjiNomoto Bolsa 1Kg x 18 | F25: AjiNomoto Bolsa 1Kg x 18 / 7754487118804 / 00803 / AB-11 | G25: 1 | H25: 109 | I25: 109 | J25: 1254.8
... A155: Belmont International Trading Corp | B155: 12/11/2025 | C155: Bill | D155: 75131 | E155: Galletas Morochas 30gr 6x 30 | F155: PCH- Galletas Morochas 30gr 6x 30 / 7613035803121 / DD-05 | G155: 4 | H155: 63.9 | I155: 255.6 | J155: 24582.44
A156: Total for Belmont International Trading Corp | I156: =I14+I15+I16+I17+I18+I19+I20+I21+I22+I23+I24+I25+I26+I27+I28+I29+I30+I31+I32+I33+I34+I35+I36+I37+I38+I39+I40+I41+I42+I43+I44+I45+I46+I47+I48+I49+I50+I51+I52+I53+I54+I55+I56+I57+I58+I59+I60+I61+I62+I63+I64+I65+I66+I67+I68+I69+I70+I71+I72+I73+I74+I75+I76+I77+I78+I79+I80+I81+I82+I83+I84+I85+I86+I87+I88+I89+I90+I91+I92+I93+I94+I95+I96+I97+I98+I99+I100+I101+I102+I103+I104+I105+I106+I107+I108+I109+I110+I111+I112+I113+I114+I115+I116+I117+I118+I119+I120+I121+I122+I123+I124+I125+I126+I127+I128+I129+I130+I131+I132+I133+I134+I135+I136+I137+I138+I139+I140+I141+I142+I143+I144+I145+I146+I147+I148+I149+I150+I151+I152+I153+I154+I155 -> 24582.44
A157: Continental Food and Beverage, inc
A158: Continental Food and Beverage, inc | B158: 03/03/2025 | C158: Bill | E158: Inca Kola Plastico 2Lt x 8 | F158: Plastico 2Lt | G158: 840 | H158: 12.73 | I158: 10693.2 | J158: 10693.2
A159: Continental Food and Beverage, inc | B159: 03/03/2025 | C159: Bill | E159: Inca Kola Regular x 24 Latas | F159: Regular | G159: 104 | H159: 10.06 | I159: 1046.24 | J159: 11739.44
A160: Continental Food and Beverage, inc | B160: 03/03/2025 | C160: Bill | E160: Inca Kola Vidrio x 24 | F160: Vidrio | G160: 70 | H160: 22.5 | I160: 1575 | J160: 13314.44
A161: Continental Food and Beverage, inc | B161: 03/03/2025 | C161: Bill | E161: Inca Kola Regular x 12 latas | F161: Regular lata x 12 | G161: 416 | H161: 4.985 | I161: 2073.76 | J161: 15388.2
A162: Continental Food and Beverage, inc | B162: 03/03/2025 | C162: Bill | E162: Inca Kola Diet Lata 12oz x 24 | F162: Diet | G162: 104 | H162: 11.94 | I162: 1241.76 | J162: 16629.96
A163: Continental Food and Beverage, inc | B163: 03/13/2025 | C163: Vendor Credit | E163: Inca Kola Plastico 2Lt x 8 | F163: Plastico 2Lt | G163: -80 | H163: 12.73 | I163: -1018.4 | J163: 15611.56
A164: Continental Food and Beverage, inc | B164: 03/13/2025 | C164: Vendor Credit | E164: Product Adjustment | F164: Used for credit memos related to price differences or missing/ damaged inventory | G164: -1 | H164: 204.88 | I164: -204.88 | J164: 15406.68
A165: Continental Food and Beverage, inc | B165: 04/09/2025 | C165: Bill | E165: Inca Kola Regular x 12 latas | F165: - BEBIDAS - INCA KOLA - REGULAR LATA 12 OZ / 12 | G165: 1664 | H165: 5.235 | I165: 8711.04 | J165: 24117.72
A166: Continental Food and Beverage, inc | B166: 04/09/2025 | C166: Bill | E166: Inca Kola Regular x 24 Latas | F166: - BEBIDAS - INCA KOLA - REGULAR- LATA 12 OZ / 24 | G166: 104 | H166: 12.44 | I166: 1293.76 | J166: 25411.48
A167: Continental Food and Beverage, inc | B167: 04/28/2025 | C167: Bill | E167: Inca Kola Regular x 12 latas | F167: - BEBIDAS - INCA KOLA - REGULAR LATA 12 OZ / 12 | G167: 416 | H167: 5.235 | I167: 2177.76 | J167: 27589.24
A168: Continental Food and Beverage, inc | B168: 04/28/2025 | C168: Bill | E168: Inca Kola Diet Lata 12oz x 24 | F168: INCA KOLA - BEBIDAS - INCA KOLA - DIET- LATA 12 OZ / 24 | G168: 208 | H168: 12.44 | I168: 2587.52 | J168: 30176.76
A169: Continental Food and Beverage, inc | B169: 04/28/2025 | C169: Bill | E169: Kola Inglesa 12oz x 24 | F169: - BEBIDAS - KOLA INGLESA - VIDRIO- VIDRIO / 24 | G169: 50 | H169: 16 | I169: 800 | J169: 30976.76
A170: Continental Food and Beverage, inc | B170: 05/14/2025 | C170: Vendor Credit | E170: Inca Kola Diet Lata 12oz x 24 | F170: INCA KOLA - BEBIDAS - INCA KOLA - DIET- LATA 12 OZ / 24 | G170: -8 | H170: 12.44 | I170: -99.52 | J170: 30877.24
...

Sheet Hoja1
D3: Valores
A4: Vendor | B4: Transaction date | C4: Product/Service full name | D4: Mín. de Rate | E4: Máx. de Rate | F4: Dif | G4: List Price | H4: Version
A5: Amazon | B5: 06/02/2025 | C5: Display Strip | D5: 5.41 | E5: 5.41 | F5: =D5=E5 -> TRUE | G5: =+A5 -> Amazon
A6: Amazon | B6: 06/04/2025 | C6: Display Strip | D6: 5.41 | E6: 5.41 | F6: =D6=E6 -> TRUE | G6: =+A6 -> Amazon
A7: Arjo Vision Trading Company LLC | B7: 03/19/2025 | C7: Volt yellow Guarana 16fl oz /15 | D7: 16.0226 | E7: 16.0226 | F7: =D7=E7 -> TRUE | G7: =+A7 -> Arjo Vision Trading Company LLC
A8: Belmont International Trading Corp | B8: 04/28/2025 | C8: AjiNomoto Bolsa 1Kg x 18 | D8: 109 | E8: 109 | F8: =D8=E8 -> TRUE | G8: =+A8 -> Belmont International Trading Corp
A9: Belmont International Trading Corp | B9: 04/28/2025 | C9: Ajinomoto Bolsa 250gr x 60 | D9: 90 | E9: 90 | F9: =D9=E9 -> TRUE | G9: =+A9 -> Belmont International Trading Corp
A10: Belmont International Trading Corp | B10: 04/28/2025 | C10: AJINOSIYAO 500ml x 24 | D10: 50.4 | E10: 50.4 | F10: =D10=E10 -> TRUE | G10: =+A10 -> Belmont International Trading Corp
A11: Belmont International Trading Corp | B11: 04/28/2025 | C11: Belmont Aceituna Bidon 104oz x 6 | D11: 106 | E11: 106 | F11: =D11=E11 -> TRUE | G11: =+A11 -> Belmont International Trading Corp
A12: Belmont International Trading Corp | B12: 04/28/2025 | C12: Belmont Aceituna Botija 20oz x 12 | D12: 39 | E12: 39 | F12: =D12=E12 -> TRUE | G12: =+A12 -> Belmont International Trading Corp
A13: Belmont International Trading Corp | B13: 04/28/2025 | C13: Belmont Aderezo de Anticucho 16oz x 12 | D13: 41 | E13: 41 | F13: =D13=E13 -> TRUE | G13: =+A13 -> Belmont International Trading Corp
A14: Belmont International Trading Corp | B14: 04/28/2025 | C14: Belmont Aji Amarillo en Salmuera 20oz x 12 | D14: 36.75 | E14: 36.75 | F14: =D14=E14 -> TRUE | G14: =+A14 -> Belmont International Trading Corp
A15: Belmont International Trading Corp | B15: 04/28/2025 | C15: Belmont Aji Amarillo entero 1Lb x 18 FROZEN | D15: 45 | E15: 45 | F15: =D15=E15 -> TRUE | G15: =+A15 -> Belmont International Trading Corp
A16: Belmont International Trading Corp | B16: 04/28/2025 | C16: Belmont Aji Amarillo pasta 8oz x 12 | D16: 23.5 | E16: 23.5 | F16: =D16=E16 -> TRUE | G16: =+A16 -> Belmont International Trading Corp
... A1452: Tradiciones Andinas | B1452: 12/03/2025 | C1452: VITAPLUSS - Maiz expandido con miel 140gr x 24 | D1452: 26.4 | E1452: 26.4 | F1452: =D1452=E1452 -> TRUE | G1452: =+A1452 -> Tradiciones Andinas
A1453: Total general | D1453: -21.5 | E1453: 204.88

Sheet Productos
A1: Product/Service full name
A2: Display Strip
A3: Volt yellow Guarana 16fl oz /15
A4: Belmont Yuyo Marino FROZEN 2.2lb x 8
A5: Belmont Chirimoya pulpa 14oz x 20
A6: Belmont Aji Amarillo entero 1Lb x 18 FROZEN
A7: Belmont Choclo desgranado 1Lb x 30 FROZEN
A8: Belmont Aji Limo 14oz x 9 FROZEN
A9: Belmont Aji Amarillo pasta 8oz x 12
A10: Belmont Aji Panca pasta 8oz x 12
A11: AJINOSIYAO 500ml x 24
A12: Ajinomoto Bolsa 250gr x 60
... A455: SOL DEL CUZCO Tableta sabor a chocolate con canela y clavo para taza 12 x 90gr

Sheet Proveedores
A1: Vendor | B1: BP
A2: Amazon | B2: =_xlfn.CONCAT(A2," ", "BP") -> Amazon BP
A3: Arjo Vision Trading Company LLC | B3: =_xlfn.CONCAT(A3," ", "BP") -> Arjo Vision Trading Company LLC BP
A4: Belmont International Trading Corp | B4: =_xlfn.CONCAT(A4," ", "BP") -> Belmont International Trading Corp BP
A5: Continental Food and Beverage, inc | B5: =_xlfn.CONCAT(A5," ", "BP") -> Continental Food and Beverage, inc BP
A6: Fiesta Mart #60 | B6: =_xlfn.CONCAT(A6," ", "BP") -> Fiesta Mart #60 BP
A7: GUIXENS FOOD GROUP, INC. | B7: =_xlfn.CONCAT(A7," ", "BP") -> GUIXENS FOOD GROUP, INC. BP
A8: Lam's Foods Inc. | B8: =_xlfn.CONCAT(A8," ", "BP") -> Lam's Foods Inc. BP
A9: La Sorpresa Store | B9: =_xlfn.CONCAT(A9," ", "BP") -> La Sorpresa Store BP
A10: Peru Chef | B10: =_xlfn.CONCAT(A10," ", "BP") -> Peru Chef BP
A11: Sam's Club | B11: =_xlfn.CONCAT(A11," ", "BP") -> Sam's Club BP
A12: SAVERS SUPERMERCADO COST + PLUS | B12: =_xlfn.CONCAT(A12," ", "BP") -> SAVERS SUPERMERCADO COST + PLUS BP
A13: Tradiciones Andinas | B13: =_xlfn.CONCAT(A13," ", "BP") -> Tradiciones Andinas BP

Sheet Base Limpia
A1: Vendor | B1: Transaction date | C1: Transaction type | D1: Num | E1: Product/Service full name | F1: Memo/Description | G1: Quantity | H1: Rate | I1: Amount | J1: Balance | K1: Se repite | L1: x | M1: y
A2: Amazon | B2: 06/02/2025 | C2: Bill | E2: Display Strip | F2: Used for product displays at retail stores | G2: 8 | H2: 5.41 | I2: 43.28 | J2: 43.28 | K2: =COUNTIF($E$2:$E$1466,E2) -> 2 | L2: =IF(G2>0,1,0) -> 1 | M2: =IF(H2>0,1,0) -> 1
A3: Amazon | B3: 06/04/2025 | C3: Expense | E3: Display Strip | F3: AMAZON MKTPL*N647V 06-03 Amzn.com/bill WA 6953 DEBIT CARD PURCHASE | G3: 8 | H3: 5.41 | I3: 43.28 | J3: 86.56 | K3: =COUNTIF($E$2:$E$1466,E3) -> 2 | L3: =IF(G3>0,1,0) -> 1 | M3: =IF(H3>0,1,0) -> 1
A4: Arjo Vision Trading Company LLC | B4: 03/19/2025 | C4: Bill | D4: 295 | E4: Volt yellow Guarana 16fl oz /15 | F4: Volt yellow Guarana lata 16fl oz /15 | G4: 15 | H4: 16.0226 | I4: 240.34 | J4: 240.34 | K4: =COUNTIF($E$2:$E$1466,E4) -> 1 | L4: =IF(G4>0,1,0) -> 1 | M4: =IF(H4>0,1,0) -> 1
A5: Belmont International Trading Corp | B5: 04/28/2025 | C5: Bill | D5: 64308 | E5: Belmont Yuyo Marino FROZEN 2.2lb x 8 | F5: Belmont Yuyo Marino FROZEN 2.2lb x 8 / 1FP-36 | G5: 1 | H5: 54 | I5: 54 | J5: 54 | K5: =COUNTIF($E$2:$E$1466,E5) -> 5 | L5: =IF(G5>0,1,0) -> 1 | M5: =IF(H5>0,1,0) -> 1
A6: Belmont International Trading Corp | B6: 04/28/2025 | C6: Bill | D6: 64308 | E6: Belmont Chirimoya pulpa 14oz x 20 | F6: Belmont Chirimoya pulpa 14oz x 20 / 859174003153 | G6: 1 | H6: 48 | I6: 48 | J6: 102 | K6: =COUNTIF($E$2:$E$1466,E6) -> 2 | L6: =IF(G6>0,1,0) -> 1 | M6: =IF(H6>0,1,0) -> 1
A7: Belmont International Trading Corp | B7: 04/28/2025 | C7: Bill | D7: 64308 | E7: Belmont Aji Amarillo entero 1Lb x 18 FROZEN | F7: BELMONT - Belmont Aji Amarillo entero 1Lb x 18 bolsas FROZEN | G7: 6 | H7: 45 | I7: 270 | J7: 372 | K7: =COUNTIF($E$2:$E$1466,E7) -> 2 | L7: =IF(G7>0,1,0) -> 1 | M7: =IF(H7>0,1,0) -> 1
A8: Belmont International Trading Corp | B8: 04/28/2025 | C8: Bill | D8: 64308 | E8: Belmont Choclo desgranado 1Lb x 30 FROZEN | F8: BELMONT - Belmont Choclo desgranado 1Lb x 30 bolsas FROZEN / 1FP-08 | G8: 6 | H8: 72.5 | I8: 435 | J8: 807 | K8: =COUNTIF($E$2:$E$1466,E8) -> 3 | L8: =IF(G8>0,1,0) -> 1 | M8: =IF(H8>0,1,0) -> 1
A9: Belmont International Trading Corp | B9: 04/28/2025 | C9: Bill | D9: 64308 | E9: Belmont Aji Limo 14oz x 9 FROZEN | F9: BELMONT - Belmont Aji Limo 14oz x 9 bolsas FROZEN | G9: 1 | H9: 20.9 | I9: 20.9 | J9: 827.9 | K9: =COUNTIF($E$2:$E$1466,E9) -> 2 | L9: =IF(G9>0,1,0) -> 1 | M9: =IF(H9>0,1,0) -> 1
A10: Belmont International Trading Corp | B10: 04/28/2025 | C10: Bill | D10: 64308 | E10: Belmont Aji Amarillo pasta 8oz x 12 | F10: BELMONT - Belmont Aji Amarillo pasta 8oz x 12 frascos de vidrio / PA-02 | G10: 3 | H10: 23.5 | I10: 70.5 | J10: 898.4 | K10: =COUNTIF($E$2:$E$1466,E10) -> 1 | L10: =IF(G10>0,1,0) -> 1 | M10: =IF(H10>0,1,0) -> 1
A11: Belmont International Trading Corp | B11: 04/28/2025 | C11: Bill | D11: 64308 | E11: Belmont Aji Panca pasta 8oz x 12 | F11: BELMONT - Belmont Aji Panca pasta 8oz x 12 frascos de vidrio / PA-08 | G11: 2 | H11: 23.5 | I11: 47 | J11: 945.4 | K11: =COUNTIF($E$2:$E$1466,E11) -> 1 | L11: =IF(G11>0,1,0) -> 1 | M11: =IF(H11>0,1,0) -> 1
A12: Belmont International Trading Corp | B12: 04/28/2025 | C12: Bill | D12: 64308 | E12: AJINOSIYAO 500ml x 24 | F12: TA- PERU - CONDIMENT PRODUCTS - AJI NO Siyau- 24 / 500 ml - 00999 | G12: 1 | H12: 50.4 | I12: 50.4 | J12: 995.8 | K12: =COUNTIF($E$2:$E$1466,E12) -> 5 | L12: =IF(G12>0,1,0) -> 1 | M12: =IF(H12>0,1,0) -> 1
A13: Belmont International Trading Corp | B13: 04/28/2025 | C13: Bill | D13: 64308 | E13: Ajinomoto Bolsa 250gr x 60 | F13: TA- PERU - CONDIMENT PRODUCTS - MSG -AJINOMOTO- 60 / 250gr - 00995 | G13: 1 | H13: 90 | I13: 90 | J13: 1085.8 | K13: =COUNTIF($E$2:$E$1466,E13) -> 7 | L13: =IF(G13>0,1,0) -> 1 | M13: =IF(H13>0,1,0) -> 1
A14: Belmont International Trading Corp | B14: 04/28/2025 | C14: Bill | D14: 64308 | E14: Chocolate Cuzco con canela y clavo 4 x 12 | F14: Chocolate Cuzco con canela y clavo 4 x 12 | G14: 1 | H14: 30 | I14: 30 | J14: 1115.8 | K14: =COUNTIF($E$2:$E$1466,E14) -> 1 | L14: =IF(G14>0,1,0) -> 1 | M14: =IF(H14>0,1,0) -> 1
A15: Belmont International Trading Corp | B15: 04/28/2025 | C15: Bill | D15: 64308 | E15: Chocolate Cuzco regular 4 x 12 | F15: Chocolate Cuzco regular 4 x 12 / 859174003672 / AB-07 | G15: 1 | H15: 30 | I15: 30 | J15: 1145.8 | K15: =COUNTIF($E$2:$E$1466,E15) -> 4 | L15: =IF(G15>0,1,0) -> 1 | M15: =IF(H15>0,1,0) -> 1
... A146: Belmont International Trading Corp | B146: 12/11/2025 | C146: Bill | D146: 75131 | E146: Galletas Morochas 30gr 6x 30 | F146: PCH- Galletas Morochas 30gr 6x 30 / 7613035803121 / DD-05 | G146: 4 | H146: 63.9 | I146: 255.6 | J146: 24582.44 | K146: =COUNTIF($E$2:$E$1466,E146) -> 6 | L146: =IF(G146>0,1,0) -> 1 | M146: =IF(H146>0,1,0) -> 1
A147: Continental Food and Beverage, inc | B147: 03/03/2025 | C147: Bill | E147: Inca Kola Plastico 2Lt x 8 | F147: Plastico 2Lt | G147: 840 | H147: 12.73 | I147: 10693.2 | J147: 10693.2 | K147: =COUNTIF($E$2:$E$1466,E147) -> 6 | L147: =IF(G147>0,1,0) -> 1 | M147: =IF(H147>0,1,0) -> 1
A148: Continental Food and Beverage, inc | B148: 03/03/2025 | C148: Bill | E148: Inca Kola Regular x 24 Latas | F148: Regular | G148: 104 | H148: 10.06 | I148: 1046.24 | J148: 11739.44 | K148: =COUNTIF($E$2:$E$1466,E148) -> 5 | L148: =IF(G148>0,1,0) -> 1 | M148: =IF(H148>0,1,0) -> 1
A149: Continental Food and Beverage, inc | B149: 03/03/2025 | C149: Bill | E149: Inca Kola Vidrio x 24 | F149: Vidrio | G149: 70 | H149: 22.5 | I149: 1575 | J149: 13314.44 | K149: =COUNTIF($E$2:$E$1466,E149) -> 3 | L149: =IF(G149>0,1,0) -> 1 | M149: =IF(H149>0,1,0) -> 1
A150: Continental Food and Beverage, inc | B150: 03/03/2025 | C150: Bill | E150: Inca Kola Regular x 12 latas | F150: Regular lata x 12 | G150: 416 | H150: 4.985 | I150: 2073.76 | J150: 15388.2 | K150: =COUNTIF($E$2:$E$1466,E150) -> 10 | L150: =IF(G150>0,1,0) -> 1 | M150: =IF(H150>0,1,0) -> 1
A151: Continental Food and Beverage, inc | B151: 03/03/2025 | C151: Bill | E151: Inca Kola Diet Lata 12oz x 24 | F151: Diet | G151: 104 | H151: 11.94 | I151: 1241.76 | J151: 16629.96 | K151: =COUNTIF($E$2:$E$1466,E151) -> 4 | L151: =IF(G151>0,1,0) -> 1 | M151: =IF(H151>0,1,0) -> 1
A152: Continental Food and Beverage, inc | B152: 03/13/2025 | C152: Vendor Credit | E152: Inca Kola Plastico 2Lt x 8 | F152: Plastico 2Lt | G152: -80 | H152: 12.73 | I152: -1018.4 | J152: 15611.56 | K152: =COUNTIF($E$2:$E$1466,E152) -> 6 | L152: =IF(G152>0,1,0) -> 0 | M152: =IF(H152>0,1,0) -> 1
A153: Continental Food and Beverage, inc | B153: 03/13/2025 | C153: Vendor Credit | E153: Product Adjustment | F153: Used for credit memos related to price differences or missing/ damaged inventory | G153: -1 | H153: 204.88 | I153: -204.88 | J153: 15406.68 | K153: =COUNTIF($E$2:$E$1466,E153) -> 1 | L153: =IF(G153>0,1,0) -> 0 | M153: =IF(H153>0,1,0) -> 1
A154: Continental Food and Beverage, inc | B154: 04/09/2025 | C154: Bill | E154: Inca Kola Regular x 12 latas | F154: - BEBIDAS - INCA KOLA - REGULAR LATA 12 OZ / 12 | G154: 1664 | H154: 5.235 | I154: 8711.04 | J154: 24117.72 | K154: =COUNTIF($E$2:$E$1466,E154) -> 10 | L154: =IF(G154>0,1,0) -> 1 | M154: =IF(H154>0,1,0) -> 1
A155: Continental Food and Beverage, inc | B155: 04/09/2025 | C155: Bill | E155: Inca Kola Regular x 24 Latas | F155: - BEBIDAS - INCA KOLA - REGULAR- LATA 12 OZ / 24 | G155: 104 | H155: 12.44 | I155: 1293.76 | J155: 25411.48 | K155: =COUNTIF($E$2:$E$1466,E155) -> 5 | L155: =IF(G155>0,1,0) -> 1 | M155: =IF(H155>0,1,0) -> 1
A156: Continental Food and Beverage, inc | B156: 04/28/2025 | C156: Bill | E156: Inca Kola Regular x 12 latas | F156: - BEBIDAS - INCA KOLA - REGULAR LATA 12 OZ / 12 | G156: 416 | H156: 5.235 | I156: 2177.76 | J156: 27589.24 | K156: =COUNTIF($E$2:$E$1466,E156) -> 10 | L156: =IF(G156>0,1,0) -> 1 | M156: =IF(H156>0,1,0) -> 1
A157: Continental Food and Beverage, inc | B157: 04/28/2025 | C157: Bill | E157: Inca Kola Diet Lata 12oz x 24 | F157: INCA KOLA - BEBIDAS - INCA KOLA - DIET- LATA 12 OZ / 24 | G157: 208 | H157: 12.44 | I157: 2587.52 | J157: 30176.76 | K157: =COUNTIF($E$2:$E$1466,E157) -> 4 | L157: =IF(G157>0,1,0) -> 1 | M157: =IF(H157>0,1,0) -> 1
A158: Continental Food and Beverage, inc | B158: 04/28/2025 | C158: Bill | E158: Kola Inglesa 12oz x 24 | F158: - BEBIDAS - KOLA INGLESA - VIDRIO- VIDRIO / 24 | G158: 50 | H158: 16 | I158: 800 | J158: 30976.76 | K158: =COUNTIF($E$2:$E$1466,E158) -> 2 | L158: =IF(G158>0,1,0) -> 1 | M158: =IF(H158>0,1,0) -> 1
A159: Continental Food and Beverage, inc | B159: 05/14/2025 | C159: Vendor Credit | E159: Inca Kola Diet Lata 12oz x 24 | F159: INCA KOLA - BEBIDAS - INCA KOLA - DIET- LATA 12 OZ / 24 | G159: -8 | H159: 12.44 | I159: -99.52 | J159: 30877.24 | K159: =COUNTIF($E$2:$E$1466,E159) -> 4 | L159: =IF(G159>0,1,0) -> 0 | M159: =IF(H159>0,1,0) -> 1
A160: Continental Food and Beverage, inc | B160: 07/08/2025 | C160: Bill | D160: 70933 | E160: Inca Kola Plastico 2Lt x 8 | F160: - BEBIDAS - INCA KOLA - PLASTICO 2LT- / 8 | G160: 240 | H160: 13.28 | I160: 3187.2 | J160: 34064.44 | K160: =COUNTIF($E$2:$E$1466,E160) -> 6 | L160: =IF(G160>0,1,0) -> 1 | M160: =IF(H160>0,1,0) -> 1
A161: Continental Food and Beverage, inc | B161: 07/08/2025 | C161: Bill | D161: 70933 | E161: Inca Kola Regular x 12 latas | F161: - BEBIDAS - INCA KOLA - REGULAR LATA 12 OZ / 12 | G161: 824 | H161: 5.235 | I161: 4313.64 | J161: 38378.08 | K161: =COUNTIF($E$2:$E$1466,E161) -> 10 | L161: =IF(G161>0,1,0) -> 1 | M161: =IF(H161>0,1,0) -> 1
A162: Continental Food and Beverage, inc | B162: 07/08/2025 | C162: Bill | D162: 70933 | E162: Inca Kola Regular x 24 Latas | F162: - BEBIDAS - INCA KOLA - REGULAR- LATA 12 OZ / 24 | G162: 312 | H162: 10.56 | I162: 3294.72 | J162: 41672.8 | K162: =COUNTIF($E$2:$E$1466,E162) -> 5 | L162: =IF(G162>0,1,0) -> 1 | M162: =IF(H162>0,1,0) -> 1
A163: Continental Food and Beverage, inc | B163: 08/21/2025 | C163: Bill | D163: 71340 | E163: Inca Kola Plastico 2Lt x 8 | F163: - BEBIDAS - INCA KOLA - PLASTICO 2LT- / 8 | G163: 240 | H163: 13.28 | I163: 3187.2 | J163: 44860 | K163: =COUNTIF($E$2:$E$1466,E163) -> 6 | L163: =IF(G163>0,1,0) -> 1 | M163: =IF(H163>0,1,0) -> 1
A164: Continental Food and Beverage, inc | B164: 08/21/2025 | C164: Bill | D164: 71340 | E164: Inca Kola Regular x 12 latas | F164: - BEBIDAS - INCA KOLA - REGULAR LATA 12 OZ / 12 | G164: 832 | H164: 5.235 | I164: 4355.52 | J164: 49215.52 | K164: =COUNTIF($E$2:$E$1466,E164) -> 10 | L164: =IF(G164>0,1,0) -> 1 | M164: =IF(H164>0,1,0) -> 1
A165: Continental Food and Beverage, inc | B165: 08/21/2025 | C165: Bill | D165: 71340 | E165: Inca Kola Diet Lata 12oz x 24 | F165: INCA KOLA - BEBIDAS - INCA KOLA - DIET- LATA 12 OZ / 24 | G165: 100 | H165: 12.44 | I165: 1244 | J165: 50459.52 | K165: =COUNTIF($E$2:$E$1466,E165) -> 4 | L165: =IF(G165>0,1,0) -> 1 | M165: =IF(H165>0,1,0) -> 1
A166: Continental Food and Beverage, inc | B166: 08/21/2025 | C166: Bill | D166: 71340 | E166: Inca Kola Vidrio x 24 | F166: - BEBIDAS - INCA KOLA - VIDRIO- 10 OZ / 24 | G166: 70 | H166: 24.25 | I166: 1697.5 | J166: 52157.02 | K166: =COUNTIF($E$2:$E$1466,E166) -> 3 | L166: =IF(G166>0,1,0) -> 1 | M166: =IF(H166>0,1,0) -> 1
A167: Continental Food and Beverage, inc | B167: 08/21/2025 | C167: Bill | D167: 71340 | E167: Kola Inglesa 12oz x 24 | F167: - BEBIDAS - KOLA INGLESA - VIDRIO- VIDRIO / 24 | G167: 50 | H167: 16 | I167: 800 | J167: 52957.02 | K167: =COUNTIF($E$2:$E$1466,E167) -> 2 | L167: =IF(G167>0,1,0) -> 1 | M167: =IF(H167>0,1,0) -> 1
A168: Continental Food and Beverage, inc | B168: 09/30/2025 | C168: Vendor Credit | D168: 10823 | E168: Inca Kola Regular x 24 Latas | F168: - BEBIDAS - INCA KOLA - REGULAR- LATA 12 OZ / 24 | G168: -100 | H168: 10.56 | I168: -1056 | J168: 51901.02 | K168: =COUNTIF($E$2:$E$1466,E168) -> 5 | L168: =IF(G168>0,1,0) -> 0 | M168: =IF(H168>0,1,0) -> 1
A169: Continental Food and Beverage, inc | B169: 09/30/2025 | C169: Vendor Credit | D169: 10823 | E169: Inca Kola Regular x 12 latas | F169: - BEBIDAS - INCA KOLA - REGULAR LATA 12 OZ / 12 | G169: -824 | H169: 5.235 | I169: -4313.64 | J169: 47587.38 | K169: =COUNTIF($E$2:$E$1466,E169) -> 10 | L169: =IF(G169>0,1,0) -> 0 | M169: =IF(H169>0,1,0) -> 1
A170: Continental Food and Beverage, inc | B170: 09/30/2025 | C170: Vendor Credit | D170: 10823 | E170: Inca Kola Regular x 12 latas | F170: - BEBIDAS - INCA KOLA - REGULAR LATA 12 OZ / 12 | G170: -832 | H170: 5.235 | I170: -4355.52 | J170: 43231.86 | K170: =COUNTIF($E$2:$E$1466,E170) -> 10 | L170: =IF(G170>0,1,0) -> 0 | M170: =IF(H170>0,1,0) -> 1
...

Sheet Base Sin Negativos
A1: Vendor | B1: Transaction date | C1: Transaction type | D1: Num | E1: Product/Service full name | F1: Memo/Description | G1: Quantity | H1: Rate | I1: Amount | J1: Balance | K1: # | L1: Repite producto? | M1: # | N1: # | O1: Repite producto en proveedor? | P1: # | Q1: # | R1: Repite precio en producto en proveedor? | S1: Final | W1: Version | X1: Detalle error | Z1: x
A2: Sam's Club | B2: 12/14/2025 | C2: Bill | E2: Agua Ozarka Texas 8 fl oz Paquete de 48 Botellas de Plástico | F2: Agua de Manantial Ozarka Texas, 8 fl oz, Paquete de 48 Botellas de Plástico | G2: 5 | H2: 7.98 | I2: 39.9 | J2: 39.9 | K2: =COUNTIF($E$2:$E$1438,E2) -> 1 | L2: =IF(K2>1,_xlfn.CONCAT("Se repite ",K2," veces"),"No se repite") -> No se repite | M2: =_xlfn.CONCAT(A2,"-",E2) -> Sam's Club-Agua Ozarka Texas 8 fl oz Paquete de 48 Botellas de Plástico | N2: =COUNTIF($M$2:$M$1438,M2) -> 1 | O2: =IF(N2>1,_xlfn.CONCAT("Se repite ",N2," veces en ",A2),"No se repite en proveedor") -> No se repite en proveedor | P2: =_xlfn.CONCAT(A2,"-",E2,"-",H2) -> Sam's Club-Agua Ozarka Texas 8 fl oz Paquete de 48 Botellas de Plástico-7.98 | Q2: =COUNTIF($P$2:$P$1438,P2) -> 1 | R2: =IF(Q2>1,_xlfn.CONCAT("Se repite ",Q2," veces el precio de ",H2),"No se repite") -> No se repite | S2: =_xlfn.CONCAT("El producto ",E2," ",O2,IF(R2="No se repite",_xlfn.CONCAT(" Una vez con el precio ",H2),_xlfn.CONCAT(", ",R2))) -> El producto Agua Ozarka Texas 8 fl oz Paquete de 48 Botellas de Plástico No se repite en proveedor Una vez con el precio 7.98 | T2: =+A2 -> Sam's Club | U2: =+E2 -> Agua Ozarka Texas 8 fl oz Paquete de 48 Botellas de Plástico | V2: =+H2 -> 7.98 | W2: =_xlfn.CONCAT(A2," ",B2) -> Sam's Club 12/14/2025 | Z2: =G2*H2 -> 39.9
A3: Peru Chef | B3: 09/11/2025 | C3: Bill | D3: 2025001378 | E3: Aji Panca Seco sin pepa 2.04kg | F3: Aji Panca Seco | G3: 1 | H3: 180 | I3: 180 | J3: 25252 | K3: =COUNTIF($E$2:$E$1438,E3) -> 2 | L3: =IF(K3>1,_xlfn.CONCAT("Se repite ",K3," veces"),"No se repite") -> Se repite 2 veces | M3: =_xlfn.CONCAT(A3,"-",E3) -> Peru Chef-Aji Panca Seco sin pepa 2.04kg | N3: =COUNTIF($M$2:$M$1438,M3) -> 2 | O3: =IF(N3>1,_xlfn.CONCAT("Se repite ",N3," veces en ",A3),"No se repite en proveedor") -> Se repite 2 veces en Peru Chef | P3: =_xlfn.CONCAT(A3,"-",E3,"-",H3) -> Peru Chef-Aji Panca Seco sin pepa 2.04kg-180 | Q3: =COUNTIF($P$2:$P$1438,P3) -> 1 | R3: =IF(Q3>1,_xlfn.CONCAT("Se repite ",Q3," veces el precio de ",H3),"No se repite") -> No se repite | S3: =_xlfn.CONCAT("El producto ",E3," ",O3,IF(R3="No se repite",_xlfn.CONCAT(" Una vez con el precio ",H3),_xlfn.CONCAT(", ",R3))) -> El producto Aji Panca Seco sin pepa 2.04kg Se repite 2 veces en Peru Chef Una vez con el precio 180 | T3: =+A3 -> Peru Chef | U3: =+E3 -> Aji Panca Seco sin pepa 2.04kg | V3: =+H3 -> 180 | W3: =_xlfn.CONCAT(A3," ",B3) -> Peru Chef 09/11/2025 | Z3: =G3*H3 -> 180
A4: Peru Chef | B4: 10/09/2025 | C4: Bill | D4: 2025001691 | E4: Aji Panca Seco sin pepa 2.04kg | F4: Aji Panca Seco | G4: 5 | H4: 40 | I4: 200 | J4: 28751.5 | K4: =COUNTIF($E$2:$E$1438,E4) -> 2 | L4: =IF(K4>1,_xlfn.CONCAT("Se repite ",K4," veces"),"No se repite") -> Se repite 2 veces | M4: =_xlfn.CONCAT(A4,"-",E4) -> Peru Chef-Aji Panca Seco sin pepa 2.04kg | N4: =COUNTIF($M$2:$M$1438,M4) -> 2 | O4: =IF(N4>1,_xlfn.CONCAT("Se repite ",N4," veces en ",A4),"No se repite en proveedor") -> Se repite 2 veces en Peru Chef | P4: =_xlfn.CONCAT(A4,"-",E4,"-",H4) -> Peru Chef-Aji Panca Seco sin pepa 2.04kg-40 | Q4: =COUNTIF($P$2:$P$1438,P4) -> 1 | R4: =IF(Q4>1,_xlfn.CONCAT("Se repite ",Q4," veces el precio de ",H4),"No se repite") -> No se repite | S4: =_xlfn.CONCAT("El producto ",E4," ",O4,IF(R4="No se repite",_xlfn.CONCAT(" Una vez con el precio ",H4),_xlfn.CONCAT(", ",R4))) -> El producto Aji Panca Seco sin pepa 2.04kg Se repite 2 veces en Peru Chef Una vez con el precio 40 | T4: =+A4 -> Peru Chef | U4: =+E4 -> Aji Panca Seco sin pepa 2.04kg | V4: =+H4 -> 40 | W4: =_xlfn.CONCAT(A4," ",B4) -> Peru Chef 10/09/2025 | Z4: =G4*H4 -> 200
A5: Belmont International Trading Corp | B5: 04/28/2025 | C5: Bill | D5: 64308 | E5: AjiNomoto Bolsa 1Kg x 18 | F5: AjiNomoto Bolsa 1Kg x 18 / 7754487118804 / 00803 / AB-11 | G5: 1 | H5: 109 | I5: 109 | J5: 1254.8 | K5: =COUNTIF($E$2:$E$1438,E5) -> 5 | L5: =IF(K5>1,_xlfn.CONCAT("Se repite ",K5," veces"),"No se repite") -> Se repite 5 veces | M5: =_xlfn.CONCAT(A5,"-",E5) -> Belmont International Trading Corp-AjiNomoto Bolsa 1Kg x 18 | N5: =COUNTIF($M$2:$M$1438,M5) -> 1 | O5: =IF(N5>1,_xlfn.CONCAT("Se repite ",N5," veces en ",A5),"No se repite en proveedor") -> No se repite en proveedor | P5: =_xlfn.CONCAT(A5,"-",E5,"-",H5) -> Belmont International Trading Corp-AjiNomoto Bolsa 1Kg x 18-109 | Q5: =COUNTIF($P$2:$P$1438,P5) -> 1 | R5: =IF(Q5>1,_xlfn.CONCAT("Se repite ",Q5," veces el precio de ",H5),"No se repite") -> No se repite | S5: =_xlfn.CONCAT("El producto ",E5," ",O5,IF(R5="No se repite",_xlfn.CONCAT(" Una vez con el precio ",H5),_xlfn.CONCAT(", ",R5))) -> El producto AjiNomoto Bolsa 1Kg x 18 No se repite en proveedor Una vez con el precio 109 | T5: =+A5 -> Belmont International Trading Corp | U5: =+E5 -> AjiNomoto Bolsa 1Kg x 18 | V5: =+H5 -> 109 | W5: =_xlfn.CONCAT(A5," ",B5) -> Belmont International Trading Corp 04/28/2025 | Z5: =G5*H5 -> 109
A6: Tradiciones Andinas | B6: 06/12/2025 | C6: Bill | D6: 480295 | E6: AjiNomoto Bolsa 1Kg x 18 | F6: AjiNomoto Bolsa 1Kg x 18 / 7754487118804 / 00803 / AB-11 | G6: 1 | H6: 85 | I6: 85 | J6: 38616.68 | K6: =COUNTIF($E$2:$E$1438,E6) -> 5 | L6: =IF(K6>1,_xlfn.CONCAT("Se repite ",K6," veces"),"No se repite") -> Se repite 5 veces | M6: =_xlfn.CONCAT(A6,"-",E6) -> Tradiciones Andinas-AjiNomoto Bolsa 1Kg x 18 | N6: =COUNTIF($M$2:$M$1438,M6) -> 4 | O6: =IF(N6>1,_xlfn.CONCAT("Se repite ",N6," veces en ",A6),"No se repite en proveedor") -> Se repite 4 veces en Tradiciones Andinas | P6: =_xlfn.CONCAT(A6,"-",E6,"-",H6) -> Tradiciones Andinas-AjiNomoto Bolsa 1Kg x 18-85 | Q6: =COUNTIF($P$2:$P$1438,P6) -> 4 | R6: =IF(Q6>1,_xlfn.CONCAT("Se repite ",Q6," veces el precio de ",H6),"No se repite") -> Se repite 4 veces el precio de 85 | S6: =_xlfn.CONCAT("El producto ",E6," ",O6,IF(R6="No se repite",_xlfn.CONCAT(" Una vez con el precio ",H6),_xlfn.CONCAT(", ",R6))) -> El producto AjiNomoto Bolsa 1Kg x 18 Se repite 4 veces en Tradiciones Andinas, Se repite 4 veces el precio de 85 | T6: =+A6 -> Tradiciones Andinas | U6: =+E6 -> AjiNomoto Bolsa 1Kg x 18 | V6: =+H6 -> 85 | W6: 1 | Z6: =G6*H6 -> 85
A7: Tradiciones Andinas | B7: 07/03/2025 | C7: Bill | D7: 482005 | E7: AjiNomoto Bolsa 1Kg x 18 | F7: AjiNomoto Bolsa 1Kg x 18 / 7754487118804 / 00803 / AB-11 | G7: 2 | H7: 85 | I7: 170 | J7: 50395.63 | K7: =COUNTIF($E$2:$E$1438,E7) -> 5 | L7: =IF(K7>1,_xlfn.CONCAT("Se repite ",K7," veces"),"No se repite") -> Se repite 5 veces | M7: =_xlfn.CONCAT(A7,"-",E7) -> Tradiciones Andinas-AjiNomoto Bolsa 1Kg x 18 | N7: =COUNTIF($M$2:$M$1438,M7) -> 4 | O7: =IF(N7>1,_xlfn.CONCAT("Se repite ",N7," veces en ",A7),"No se repite en proveedor") -> Se repite 4 veces en Tradiciones Andinas | P7: =_xlfn.CONCAT(A7,"-",E7,"-",H7) -> Tradiciones Andinas-AjiNomoto Bolsa 1Kg x 18-85 | Q7: =COUNTIF($P$2:$P$1438,P7) -> 4 | R7: =IF(Q7>1,_xlfn.CONCAT("Se repite ",Q7," veces el precio de ",H7),"No se repite") -> Se repite 4 veces el precio de 85 | S7: =_xlfn.CONCAT("El producto ",E7," ",O7,IF(R7="No se repite",_xlfn.CONCAT(" Una vez con el precio ",H7),_xlfn.CONCAT(", ",R7))) -> El producto AjiNomoto Bolsa 1Kg x 18 Se repite 4 veces en Tradiciones Andinas, Se repite 4 veces el precio de 85 | T7: =+A7 -> Tradiciones Andinas | U7: =+E7 -> AjiNomoto Bolsa 1Kg x 18 | V7: =+H7 -> 85 | W7: =_xlfn.CONCAT(A7," ",B7) -> Tradiciones Andinas 07/03/2025 | Z7: =G7*H7 -> 170
A8: Tradiciones Andinas | B8: 09/24/2025 | C8: Bill | D8: 487860 | E8: AjiNomoto Bolsa 1Kg x 18 | F8: AjiNomoto Bolsa 1Kg x 18 / 7754487118804 / 00803 / AB-11 | G8: 1 | H8: 85 | I8: 85 | J8: 80699.94 | K8: =COUNTIF($E$2:$E$1438,E8) -> 5 | L8: =IF(K8>1,_xlfn.CONCAT("Se repite ",K8," veces"),"No se repite") -> Se repite 5 veces | M8: =_xlfn.CONCAT(A8,"-",E8) -> Tradiciones Andinas-AjiNomoto Bolsa 1Kg x 18 | N8: =COUNTIF($M$2:$M$1438,M8) -> 4 | O8: =IF(N8>1,_xlfn.CONCAT("Se repite ",N8," veces en ",A8),"No se repite en proveedor") -> Se repite 4 veces en Tradiciones Andinas | P8: =_xlfn.CONCAT(A8,"-",E8,"-",H8) -> Tradiciones Andinas-AjiNomoto Bolsa 1Kg x 18-85 | Q8: =COUNTIF($P$2:$P$1438,P8) -> 4 | R8: =IF(Q8>1,_xlfn.CONCAT("Se repite ",Q8," veces el precio de ",H8),"No se repite") -> Se repite 4 veces el precio de 85 | S8: =_xlfn.CONCAT("El producto ",E8," ",O8,IF(R8="No se repite",_xlfn.CONCAT(" Una vez con el precio ",H8),_xlfn.CONCAT(", ",R8))) -> El producto AjiNomoto Bolsa 1Kg x 18 Se repite 4 veces en Tradiciones Andinas, Se repite 4 veces el precio de 85 | T8: =+A8 -> Tradiciones Andinas | U8: =+E8 -> AjiNomoto Bolsa 1Kg x 18 | V8: =+H8 -> 85 | W8: =_xlfn.CONCAT(A8," ",B8) -> Tradiciones Andinas 09/24/2025 | Z8: =G8*H8 -> 85
A9: Tradiciones Andinas | B9: 11/28/2025 | C9: Bill | D9: 492743 | E9: AjiNomoto Bolsa 1Kg x 18 | F9: AjiNomoto Bolsa 1Kg x 18 / 7754487118804 / 00803 / AB-11 | G9: 2 | H9: 85 | I9: 170 | J9: 107432.13 | K9: =COUNTIF($E$2:$E$1438,E9) -> 5 | L9: =IF(K9>1,_xlfn.CONCAT("Se repite ",K9," veces"),"No se repite") -> Se repite 5 veces | M9: =_xlfn.CONCAT(A9,"-",E9) -> Tradiciones Andinas-AjiNomoto Bolsa 1Kg x 18 | N9: =COUNTIF($M$2:$M$1438,M9) -> 4 | O9: =IF(N9>1,_xlfn.CONCAT("Se repite ",N9," veces en ",A9),"No se repite en proveedor") -> Se repite 4 veces en Tradiciones Andinas | P9: =_xlfn.CONCAT(A9,"-",E9,"-",H9) -> Tradiciones Andinas-AjiNomoto Bolsa 1Kg x 18-85 | Q9: =COUNTIF($P$2:$P$1438,P9) -> 4 | R9: =IF(Q9>1,_xlfn.CONCAT("Se repite ",Q9," veces el precio de ",H9),"No se repite") -> Se repite 4 veces el precio de 85 | S9: =_xlfn.CONCAT("El producto ",E9," ",O9,IF(R9="No se repite",_xlfn.CONCAT(" Una vez con el precio ",H9),_xlfn.CONCAT(", ",R9))) -> El producto AjiNomoto Bolsa 1Kg x 18 Se repite 4 veces en Tradiciones Andinas, Se repite 4 veces el precio de 85 | T9: =+A9 -> Tradiciones Andinas | U9: =+E9 -> AjiNomoto Bolsa 1Kg x 18 | V9: =+H9 -> 85 | W9: =_xlfn.CONCAT(A9," ",B9) -> Tradiciones Andinas 11/28/2025 | Z9: =G9*H9 -> 170
A10: Belmont International Trading Corp | B10: 04/28/2025 | C10: Bill | D10: 64308 | E10: Ajinomoto Bolsa 250gr x 60 | F10: TA- PERU - CONDIMENT PRODUCTS - MSG -AJINOMOTO- 60 / 250gr - 00995 | G10: 1 | H10: 90 | I10: 90 | J10: 1085.8 | K10: =COUNTIF($E$2:$E$1438,E10) -> 7 | L10: =IF(K10>1,_xlfn.CONCAT("Se repite ",K10," veces"),"No se repite") -> Se repite 7 veces | M10: =_xlfn.CONCAT(A10,"-",E10) -> Belmont International Trading Corp-Ajinomoto Bolsa 250gr x 60 | N10: =COUNTIF($M$2:$M$1438,M10) -> 1 | O10: =IF(N10>1,_xlfn.CONCAT("Se repite ",N10," veces en ",A10),"No se repite en proveedor") -> No se repite en proveedor | P10: =_xlfn.CONCAT(A10,"-",E10,"-",H10) -> Belmont International Trading Corp-Ajinomoto Bolsa 250gr x 60-90 | Q10: =COUNTIF($P$2:$P$1438,P10) -> 1 | R10: =IF(Q10>1,_xlfn.CONCAT("Se repite ",Q10," veces el precio de ",H10),"No se repite") -> No se repite | S10: =_xlfn.CONCAT("El producto ",E10," ",O10,IF(R10="No se repite",_xlfn.CONCAT(" Una vez con el precio ",H10),_xlfn.CONCAT(", ",R10))) -> El producto Ajinomoto Bolsa 250gr x 60 No se repite en proveedor Una vez con el precio 90 | T10: =+A10 -> Belmont International Trading Corp | U10: =+E10 -> Ajinomoto Bolsa 250gr x 60 | V10: =+H10 -> 90 | W10: =_xlfn.CONCAT(A10," ",B10) -> Belmont International Trading Corp 04/28/2025 | Z10: =G10*H10 -> 90
A11: Peru Chef | B11: 03/26/2025 | C11: Bill | E11: Ajinomoto Bolsa 250gr x 60 | F11: MSG -AJINOMOTO | G11: 1 | H11: 99 | I11: 99 | J11: 984.8 | K11: =COUNTIF($E$2:$E$1438,E11) -> 7 | L11: =IF(K11>1,_xlfn.CONCAT("Se repite ",K11," veces"),"No se repite") -> Se repite 7 veces | M11: =_xlfn.CONCAT(A11,"-",E11) -> Peru Chef-Ajinomoto Bolsa 250gr x 60 | N11: =COUNTIF($M$2:$M$1438,M11) -> 2 | O11: =IF(N11>1,_xlfn.CONCAT("Se repite ",N11," veces en ",A11),"No se repite en proveedor") -> Se repite 2 veces en Peru Chef | P11: =_xlfn.CONCAT(A11,"-",E11,"-",H11) -> Peru Chef-Ajinomoto Bolsa 250gr x 60-99 | Q11: =COUNTIF($P$2:$P$1438,P11) -> 2 | R11: =IF(Q11>1,_xlfn.CONCAT("Se repite ",Q11," veces el precio de ",H11),"No se repite") -> Se repite 2 veces el precio de 99 | S11: =_xlfn.CONCAT("El producto ",E11," ",O11,IF(R11="No se repite",_xlfn.CONCAT(" Una vez con el precio ",H11),_xlfn.CONCAT(", ",R11))) -> El producto Ajinomoto Bolsa 250gr x 60 Se repite 2 veces en Peru Chef, Se repite 2 veces el precio de 99 | T11: =+A11 -> Peru Chef | U11: =+E11 -> Ajinomoto Bolsa 250gr x 60 | V11: =+H11 -> 99 | W11: =_xlfn.CONCAT(A11," ",B11) -> Peru Chef 03/26/2025 | Z11: =G11*H11 -> 99
A12: Peru Chef | B12: 04/10/2025 | C12: Bill | D12: 55130 | E12: Ajinomoto Bolsa 250gr x 60 | F12: MSG -AJINOMOTO | G12: 1 | H12: 99 | I12: 99 | J12: 3231 | K12: =COUNTIF($E$2:$E$1438,E12) -> 7 | L12: =IF(K12>1,_xlfn.CONCAT("Se repite ",K12," veces"),"No se repite") -> Se repite 7 veces | M12: =_xlfn.CONCAT(A12,"-",E12) -> Peru Chef-Ajinomoto Bolsa 250gr x 60 | N12: =COUNTIF($M$2:$M$1438,M12) -> 2 | O12: =IF(N12>1,_xlfn.CONCAT("Se repite ",N12," veces en ",A12),"No se repite en proveedor") -> Se repite 2 veces en Peru Chef | P12: =_xlfn.CONCAT(A12,"-",E12,"-",H12) -> Peru Chef-Ajinomoto Bolsa 250gr x 60-99 | Q12: =COUNTIF($P$2:$P$1438,P12) -> 2 | R12: =IF(Q12>1,_xlfn.CONCAT("Se repite ",Q12," veces el precio de ",H12),"No se repite") -> Se repite 2 veces el precio de 99 | S12: =_xlfn.CONCAT("El producto ",E12," ",O12,IF(R12="No se repite",_xlfn.CONCAT(" Una vez con el precio ",H12),_xlfn.CONCAT(", ",R12))) -> El producto Ajinomoto Bolsa 250gr x 60 Se repite 2 veces en Peru Chef, Se repite 2 veces el precio de 99 | T12: =+A12 -> Peru Chef | U12: =+E12 -> Ajinomoto Bolsa 250gr x 60 | V12: =+H12 -> 99 | W12: =_xlfn.CONCAT(A12," ",B12) -> Peru Chef 04/10/2025 | Z12: =G12*H12 -> 99
A13: Tradiciones Andinas | B13: 04/25/2025 | C13: Bill | D13: 476974 | E13: Ajinomoto Bolsa 250gr x 60 | F13: MSG -AJINOMOTO | G13: 3 | H13: 69 | I13: 207 | J13: 14449.28 | K13: =COUNTIF($E$2:$E$1438,E13) -> 7 | L13: =IF(K13>1,_xlfn.CONCAT("Se repite ",K13," veces"),"No se repite") -> Se repite 7 veces | M13: =_xlfn.CONCAT(A13,"-",E13) -> Tradiciones Andinas-Ajinomoto Bolsa 250gr x 60 | N13: =COUNTIF($M$2:$M$1438,M13) -> 4 | O13: =IF(N13>1,_xlfn.CONCAT("Se repite ",N13," veces en ",A13),"No se repite en proveedor") -> Se repite 4 veces en Tradiciones Andinas | P13: =_xlfn.CONCAT(A13,"-",E13,"-",H13) -> Tradiciones Andinas-Ajinomoto Bolsa 250gr x 60-69 | Q13: =COUNTIF($P$2:$P$1438,P13) -> 1 | R13: =IF(Q13>1,_xlfn.CONCAT("Se repite ",Q13," veces el precio de ",H13),"No se repite") -> No se repite | S13: =_xlfn.CONCAT("El producto ",E13," ",O13,IF(R13="No se repite",_xlfn.CONCAT(" Una vez con el precio ",H13),_xlfn.CONCAT(", ",R13))) -> El producto Ajinomoto Bolsa 250gr x 60 Se repite 4 veces en Tradiciones Andinas Una vez con el precio 69 | T13: =+A13 -> Tradiciones Andinas | U13: =+E13 -> Ajinomoto Bolsa 250gr x 60 | V13: =+H13 -> 69 | W13: =_xlfn.CONCAT(A13," ",B13) -> Tradiciones Andinas 04/25/2025 | Z13: =G13*H13 -> 207
A14: Tradiciones Andinas | B14: 06/12/2025 | C14: Bill | D14: 480295 | E14: Ajinomoto Bolsa 250gr x 60 | F14: TA- PERU - CONDIMENT PRODUCTS - MSG -AJINOMOTO- 60 / 250gr - 00995 | G14: 5 | H14: 73.8 | I14: 369 | J14: 38531.68 | K14: =COUNTIF($E$2:$E$1438,E14) -> 7 | L14: =IF(K14>1,_xlfn.CONCAT("Se repite ",K14," veces"),"No se repite") -> Se repite 7 veces | M14: =_xlfn.CONCAT(A14,"-",E14) -> Tradiciones Andinas-Ajinomoto Bolsa 250gr x 60 | N14: =COUNTIF($M$2:$M$1438,M14) -> 4 | O14: =IF(N14>1,_xlfn.CONCAT("Se repite ",N14," veces en ",A14),"No se repite en proveedor") -> Se repite 4 veces en Tradiciones Andinas | P14: =_xlfn.CONCAT(A14,"-",E14,"-",H14) -> Tradiciones Andinas-Ajinomoto Bolsa 250gr x 60-73.8 | Q14: =COUNTIF($P$2:$P$1438,P14) -> 3 | R14: =IF(Q14>1,_xlfn.CONCAT("Se repite ",Q14," veces el precio de ",H14),"No se repite") -> Se repite 3 veces el precio de 73.8 | S14: =_xlfn.CONCAT("El producto ",E14," ",O14,IF(R14="No se repite",_xlfn.CONCAT(" Una vez con el precio ",H14),_xlfn.CONCAT(", ",R14))) -> El producto Ajinomoto Bolsa 250gr x 60 Se repite 4 veces en Tradiciones Andinas, Se repite 3 veces el precio de 73.8 | T14: =+A14 -> Tradiciones Andinas | U14: =+E14 -> Ajinomoto Bolsa 250gr x 60 | V14: =+H14 -> 73.8 | W14: =_xlfn.CONCAT(A14," ",B14) -> Tradiciones Andinas 06/12/2025 | Z14: =G14*H14 -> 369
A15: Tradiciones Andinas | B15: 09/24/2025 | C15: Bill | D15: 487860 | E15: Ajinomoto Bolsa 250gr x 60 | F15: TA- PERU - CONDIMENT PRODUCTS - MSG -AJINOMOTO- 60 / 250gr - 00995 | G15: 3 | H15: 73.8 | I15: 221.4 | J15: 80614.94 | K15: =COUNTIF($E$2:$E$1438,E15) -> 7 | L15: =IF(K15>1,_xlfn.CONCAT("Se repite ",K15," veces"),"No se repite") -> Se repite 7 veces | M15: =_xlfn.CONCAT(A15,"-",E15) -> Tradiciones Andinas-Ajinomoto Bolsa 250gr x 60 | N15: =COUNTIF($M$2:$M$1438,M15) -> 4 | O15: =IF(N15>1,_xlfn.CONCAT("Se repite ",N15," veces en ",A15),"No se repite en proveedor") -> Se repite 4 veces en Tradiciones Andinas | P15: =_xlfn.CONCAT(A15,"-",E15,"-",H15) -> Tradiciones Andinas-Ajinomoto Bolsa 250gr x 60-73.8 | Q15: =COUNTIF($P$2:$P$1438,P15) -> 3 | R15: =IF(Q15>1,_xlfn.CONCAT("Se repite ",Q15," veces el precio de ",H15),"No se repite") -> Se repite 3 veces el precio de 73.8 | S15: =_xlfn.CONCAT("El producto ",E15," ",O15,IF(R15="No se repite",_xlfn.CONCAT(" Una vez con el precio ",H15),_xlfn.CONCAT(", ",R15))) -> El producto Ajinomoto Bolsa 250gr x 60 Se repite 4 veces en Tradiciones Andinas, Se repite 3 veces el precio de 73.8 | T15: =+A15 -> Tradiciones Andinas | U15: =+E15 -> Ajinomoto Bolsa 250gr x 60 | V15: =+H15 -> 73.8 | W15: =_xlfn.CONCAT(A15," ",B15) -> Tradiciones Andinas 09/24/2025 | Z15: =G15*H15 -> 221.4
A16: Tradiciones Andinas | B16: 11/28/2025 | C16: Bill | D16: 492743 | E16: Ajinomoto Bolsa 250gr x 60 | F16: TA- PERU - CONDIMENT PRODUCTS - MSG -AJINOMOTO- 60 / 250gr - 00995 | G16: 4 | H16: 73.8 | I16: 295.2 | J16: 107262.13 | K16: =COUNTIF($E$2:$E$1438,E16) -> 7 | L16: =IF(K16>1,_xlfn.CONCAT("Se repite ",K16," veces"),"No se repite") -> Se repite 7 veces | M16: =_xlfn.CONCAT(A16,"-",E16) -> Tradiciones Andinas-Ajinomoto Bolsa 250gr x 60 | N16: =COUNTIF($M$2:$M$1438,M16) -> 4 | O16: =IF(N16>1,_xlfn.CONCAT("Se repite ",N16," veces en ",A16),"No se repite en proveedor") -> Se repite 4 veces en Tradiciones Andinas | P16: =_xlfn.CONCAT(A16,"-",E16,"-",H16) -> Tradiciones Andinas-Ajinomoto Bolsa 250gr x 60-73.8 | Q16: =COUNTIF($P$2:$P$1438,P16) -> 3 | R16: =IF(Q16>1,_xlfn.CONCAT("Se repite ",Q16," veces el precio de ",H16),"No se repite") -> Se repite 3 veces el precio de 73.8 | S16: =_xlfn.CONCAT("El producto ",E16," ",O16,IF(R16="No se repite",_xlfn.CONCAT(" Una vez con el precio ",H16),_xlfn.CONCAT(", ",R16))) -> El producto Ajinomoto Bolsa 250gr x 60 Se repite 4 veces en Tradiciones Andinas, Se repite 3 veces el precio de 73.8 | T16: =+A16 -> Tradiciones Andinas | U16: =+E16 -> Ajinomoto Bolsa 250gr x 60 | V16: =+H16 -> 73.8 | W16: =_xlfn.CONCAT(A16," ",B16) -> Tradiciones Andinas 11/28/2025 | Z16: =G16*H16 -> 295.2
A17: Tradiciones Andinas | B17: 04/25/2025 | C17: Bill | D17: 476974 | E17: AjiNomoto Bolsa 500g x 30 | F17: AjiNomoto Bolsa 500g x 30 - TA | G17: 6 | H17: 71 | I17: 426 | J17: 14875.28 | K17: =COUNTIF($E$2:$E$1438,E17) -> 5 | L17: =IF(K17>1,_xlfn.CONCAT("Se repite ",K17," veces"),"No se repite") -> Se repite 5 veces | M17: =_xlfn.CONCAT(A17,"-",E17) -> Tradiciones Andinas-AjiNomoto Bolsa 500g x 30 | N17: =COUNTIF($M$2:$M$1438,M17) -> 5 | O17: =IF(N17>1,_xlfn.CONCAT("Se repite ",N17," veces en ",A17),"No se repite en proveedor") -> Se repite 5 veces en Tradiciones Andinas | P17: =_xlfn.CONCAT(A17,"-",E17,"-",H17) -> Tradiciones Andinas-AjiNomoto Bolsa 500g x 30-71 | Q17: =COUNTIF($P$2:$P$1438,P17) -> 1 | R17: =IF(Q17>1,_xlfn.CONCAT("Se repite ",Q17," veces el precio de ",H17),"No se repite") -> No se repite | S17: =_xlfn.CONCAT("El producto ",E17," ",O17,IF(R17="No se repite",_xlfn.CONCAT(" Una vez con el precio ",H17),_xlfn.CONCAT(", ",R17))) -> El producto AjiNomoto Bolsa 500g x 30 Se repite 5 veces en Tradiciones Andinas Una vez con el precio 71 | T17: =+A17 -> Tradiciones Andinas | U17: =+E17 -> AjiNomoto Bolsa 500g x 30 | V17: =+H17 -> 71 | W17: =_xlfn.CONCAT(A17," ",B17) -> Tradiciones Andinas 04/25/2025 | Z17: =G17*H17 -> 426
A18: Tradiciones Andinas | B18: 05/19/2025 | C18: Bill | D18: 478734 | E18: AjiNomoto Bolsa 500g x 30 | F18: T.A AjiNomoto Bolsa 500g x 30 / 00804 | G18: 2 | H18: 75.97 | I18: 151.94 | J18: 25794.28 | K18: =COUNTIF($E$2:$E$1438,E18) -> 5 | L18: =IF(K18>1,_xlfn.CONCAT("Se repite ",K18," veces"),"No se repite") -> Se repite 5 veces | M18: =_xlfn.CONCAT(A18,"-",E18) -> Tradiciones Andinas-AjiNomoto Bolsa 500g x 30 | N18: =COUNTIF($M$2:$M$1438,M18) -> 5 | O18: =IF(N18>1,_xlfn.CONCAT("Se repite ",N18," veces en ",A18),"No se repite en proveedor") -> Se repite 5 veces en Tradiciones Andinas | P18: =_xlfn.CONCAT(A18,"-",E18,"-",H18) -> Tradiciones Andinas-AjiNomoto Bolsa 500g x 30-75.97 | Q18: =COUNTIF($P$2:$P$1438,P18) -> 4 | R18: =IF(Q18>1,_xlfn.CONCAT("Se repite ",Q18," veces el precio de ",H18),"No se repite") -> Se repite 4 veces el precio de 75.97 | S18: =_xlfn.CONCAT("El producto ",E18," ",O18,IF(R18="No se repite",_xlfn.CONCAT(" Una vez con el precio ",H18),_xlfn.CONCAT(", ",R18))) -> El producto AjiNomoto Bolsa 500g x 30 Se repite 5 veces en Tradiciones Andinas, Se repite 4 veces el precio de 75.97 | T18: =+A18 -> Tradiciones Andinas | U18: =+E18 -> AjiNomoto Bolsa 500g x 30 | V18: =+H18 -> 75.97 | W18: =_xlfn.CONCAT(A18," ",B18) -> Tradiciones Andinas 05/19/2025 | Z18: =G18*H18 -> 151.94
A19: Tradiciones Andinas | B19: 06/12/2025 | C19: Bill | D19: 480295 | E19: AjiNomoto Bolsa 500g x 30 | F19: T.A AjiNomoto Bolsa 500g x 30 / 00804 | G19: 1 | H19: 75.97 | I19: 75.97 | J19: 38692.65 | K19: =COUNTIF($E$2:$E$1438,E19) -> 5 | L19: =IF(K19>1,_xlfn.CONCAT("Se repite ",K19," veces"),"No se repite") -> Se repite 5 veces | M19: =_xlfn.CONCAT(A19,"-",E19) -> Tradiciones Andinas-AjiNomoto Bolsa 500g x 30 | N19: =COUNTIF($M$2:$M$1438,M19) -> 5 | O19: =IF(N19>1,_xlfn.CONCAT("Se repite ",N19," veces en ",A19),"No se repite en proveedor") -> Se repite 5 veces en Tradiciones Andinas | P19: =_xlfn.CONCAT(A19,"-",E19,"-",H19) -> Tradiciones Andinas-AjiNomoto Bolsa 500g x 30-75.97 | Q19: =COUNTIF($P$2:$P$1438,P19) -> 4 | R19: =IF(Q19>1,_xlfn.CONCAT("Se repite ",Q19," veces el precio de ",H19),"No se repite") -> Se repite 4 veces el precio de 75.97 | S19: =_xlfn.CONCAT("El producto ",E19," ",O19,IF(R19="No se repite",_xlfn.CONCAT(" Una vez con el precio ",H19),_xlfn.CONCAT(", ",R19))) -> El producto AjiNomoto Bolsa 500g x 30 Se repite 5 veces en Tradiciones Andinas, Se repite 4 veces el precio de 75.97 | T19: =+A19 -> Tradiciones Andinas | U19: =+E19 -> AjiNomoto Bolsa 500g x 30 | V19: =+H19 -> 75.97 | W19: =_xlfn.CONCAT(A19," ",B19) -> Tradiciones Andinas 06/12/2025 | Z19: =G19*H19 -> 75.97
A20: Tradiciones Andinas | B20: 07/03/2025 | C20: Bill | D20: 482005 | E20: AjiNomoto Bolsa 500g x 30 | F20: T.A AjiNomoto Bolsa 500g x 30 / 00804 | G20: 4 | H20: 75.97 | I20: 303.88 | J20: 50699.51 | K20: =COUNTIF($E$2:$E$1438,E20) -> 5 | L20: =IF(K20>1,_xlfn.CONCAT("Se repite ",K20," veces"),"No se repite") -> Se repite 5 veces | M20: =_xlfn.CONCAT(A20,"-",E20) -> Tradiciones Andinas-AjiNomoto Bolsa 500g x 30 | N20: =COUNTIF($M$2:$M$1438,M20) -> 5 | O20: =IF(N20>1,_xlfn.CONCAT("Se repite ",N20," veces en ",A20),"No se repite en proveedor") -> Se repite 5 veces en Tradiciones Andinas | P20: =_xlfn.CONCAT(A20,"-",E20,"-",H20) -> Tradiciones Andinas-AjiNomoto Bolsa 500g x 30-75.97 | Q20: =COUNTIF($P$2:$P$1438,P20) -> 4 | R20: =IF(Q20>1,_xlfn.CONCAT("Se repite ",Q20," veces el precio de ",H20),"No se repite") -> Se repite 4 veces el precio de 75.97 | S20: =_xlfn.CONCAT("El producto ",E20," ",O20,IF(R20="No se repite",_xlfn.CONCAT(" Una vez con el precio ",H20),_xlfn.CONCAT(", ",R20))) -> El producto AjiNomoto Bolsa 500g x 30 Se repite 5 veces en Tradiciones Andinas, Se repite 4 veces el precio de 75.97 | T20: =+A20 -> Tradiciones Andinas | U20: =+E20 -> AjiNomoto Bolsa 500g x 30 | V20: =+H20 -> 75.97 | W20: =_xlfn.CONCAT(A20," ",B20) -> Tradiciones Andinas 07/03/2025 | Z20: =G20*H20 -> 303.88
A21: Tradiciones Andinas | B21: 09/24/2025 | C21: Bill | D21: 487860 | E21: AjiNomoto Bolsa 500g x 30 | F21: T.A AjiNomoto Bolsa 500g x 30 / 00804 | G21: 3 | H21: 75.97 | I21: 227.91 | J21: 80927.85 | K21: =COUNTIF($E$2:$E$1438,E21) -> 5 | L21: =IF(K21>1,_xlfn.CONCAT("Se repite ",K21," veces"),"No se repite") -> Se repite 5 veces | M21: =_xlfn.CONCAT(A21,"-",E21) -> Tradiciones Andinas-AjiNomoto Bolsa 500g x 30 | N21: =COUNTIF($M$2:$M$1438,M21) -> 5 | O21: =IF(N21>1,_xlfn.CONCAT("Se repite ",N21," veces en ",A21),"No se repite en proveedor") -> Se repite 5 veces en Tradiciones Andinas | P21: =_xlfn.CONCAT(A21,"-",E21,"-",H21) -> Tradiciones Andinas-AjiNomoto Bolsa 500g x 30-75.97 | Q21: =COUNTIF($P$2:$P$1438,P21) -> 4 | R21: =IF(Q21>1,_xlfn.CONCAT("Se repite ",Q21," veces el precio de ",H21),"No se repite") -> Se repite 4 veces el precio de 75.97 | S21: =_xlfn.CONCAT("El producto ",E21," ",O21,IF(R21="No se repite",_xlfn.CONCAT(" Una vez con el precio ",H21),_xlfn.CONCAT(", ",R21))) -> El producto AjiNomoto Bolsa 500g x 30 Se repite 5 veces en Tradiciones Andinas, Se repite 4 veces el precio de 75.97 | T21: =+A21 -> Tradiciones Andinas | U21: =+E21 -> AjiNomoto Bolsa 500g x 30 | V21: =+H21 -> 75.97 | W21: =_xlfn.CONCAT(A21," ",B21) -> Tradiciones Andinas 09/24/2025 | Z21: =G21*H21 -> 227.91
A22: Belmont International Trading Corp | B22: 04/28/2025 | C22: Bill | D22: 64308 | E22: AJINOSIYAO 500ml x 24 | F22: TA- PERU - CONDIMENT PRODUCTS - AJI NO Siyau- 24 / 500 ml - 00999 | G22: 1 | H22: 50.4 | I22: 50.4 | J22: 995.8 | K22: =COUNTIF($E$2:$E$1438,E22) -> 5 | L22: =IF(K22>1,_xlfn.CONCAT("Se repite ",K22," veces"),"No se repite") -> Se repite 5 veces | M22: =_xlfn.CONCAT(A22,"-",E22) -> Belmont International Trading Corp-AJINOSIYAO 500ml x 24 | N22: =COUNTIF($M$2:$M$1438,M22) -> 1 | O22: =IF(N22>1,_xlfn.CONCAT("Se repite ",N22," veces en ",A22),"No se repite en proveedor") -> No se repite en proveedor | P22: =_xlfn.CONCAT(A22,"-",E22,"-",H22) -> Belmont International Trading Corp-AJINOSIYAO 500ml x 24-50.4 | Q22: =COUNTIF($P$2:$P$1438,P22) -> 1 | R22: =IF(Q22>1,_xlfn.CONCAT("Se repite ",Q22," veces el precio de ",H22),"No se repite") -> No se repite | S22: =_xlfn.CONCAT("El producto ",E22," ",O22,IF(R22="No se repite",_xlfn.CONCAT(" Una vez con el precio ",H22),_xlfn.CONCAT(", ",R22))) -> El producto AJINOSIYAO 500ml x 24 No se repite en proveedor Una vez con el precio 50.4 | T22: =+A22 -> Belmont International Trading Corp | U22: =+E22 -> AJINOSIYAO 500ml x 24 | V22: =+H22 -> 50.4 | W22: =_xlfn.CONCAT(A22," ",B22) -> Belmont International Trading Corp 04/28/2025 | Z22: =G22*H22 -> 50.4
A23: Peru Chef | B23: 08/11/2025 | C23: Bill | D23: 56352 | E23: AJINOSIYAO 500ml x 24 | F23: TA- PERU - CONDIMENT PRODUCTS - AJI NO Siyau- 24 / 500 ml - 00999 | G23: 1 | H23: 45 | I23: 45 | J23: 14643.5 | K23: =COUNTIF($E$2:$E$1438,E23) -> 5 | L23: =IF(K23>1,_xlfn.CONCAT("Se repite ",K23," veces"),"No se repite") -> Se repite 5 veces | M23: =_xlfn.CONCAT(A23,"-",E23) -> Peru Chef-AJINOSIYAO 500ml x 24 | N23: =COUNTIF($M$2:$M$1438,M23) -> 1 | O23: =IF(N23>1,_xlfn.CONCAT("Se repite ",N23," veces en ",A23),"No se repite en proveedor") -> No se repite en proveedor | P23: =_xlfn.CONCAT(A23,"-",E23,"-",H23) -> Peru Chef-AJINOSIYAO 500ml x 24-45 | Q23: =COUNTIF($P$2:$P$1438,P23) -> 1 | R23: =IF(Q23>1,_xlfn.CONCAT("Se repite ",Q23," veces el precio de ",H23),"No se repite") -> No se repite | S23: =_xlfn.CONCAT("El producto ",E23," ",O23,IF(R23="No se repite",_xlfn.CONCAT(" Una vez con el precio ",H23),_xlfn.CONCAT(", ",R23))) -> El producto AJINOSIYAO 500ml x 24 No se repite en proveedor Una vez con el precio 45 | T23: =+A23 -> Peru Chef | U23: =+E23 -> AJINOSIYAO 500ml x 24 | V23: =+H23 -> 45 | W23: =_xlfn.CONCAT(A23," ",B23) -> Peru Chef 08/11/2025 | Z23: =G23*H23 -> 45
... A26: Tradiciones Andinas | B26: 11/28/2025 | C26: Bill | D26: 492743 | E26: AJINOSIYAO 500ml x 24 | F26: TA- PERU - CONDIMENT PRODUCTS - AJI NO Siyau- 24 / 500 ml - 00999 | G26: 3 | H26: 28.8 | I26: 86.4 | J26: 107518.53 | K26: =COUNTIF($E$2:$E$1438,E26) -> 5 | L26: =IF(K26>1,_xlfn.CONCAT("Se repite ",K26," veces"),"No se repite") -> Se repite 5 veces | M26: =_xlfn.CONCAT(A26,"-",E26) -> Tradiciones Andinas-AJINOSIYAO 500ml x 24 | N26: =COUNTIF($M$2:$M$1438,M26) -> 3 | O26: =IF(N26>1,_xlfn.CONCAT("Se repite ",N26," veces en ",A26),"No se repite en proveedor") -> Se repite 3 veces en Tradiciones Andinas | P26: =_xlfn.CONCAT(A26,"-",E26,"-",H26) -> Tradiciones Andinas-AJINOSIYAO 500ml x 24-28.8 | Q26: =COUNTIF($P$2:$P$1438,P26) -> 3 | R26: =IF(Q26>1,_xlfn.CONCAT("Se repite ",Q26," veces el precio de ",H26),"No se repite") -> Se repite 3 veces el precio de 28.8 | S26: =_xlfn.CONCAT("El producto ",E26," ",O26,IF(R26="No se repite",_xlfn.CONCAT(" Una vez con el precio ",H26),_xlfn.CONCAT(", ",R26))) -> El producto AJINOSIYAO 500ml x 24 Se repite 3 veces en Tradiciones Andinas, Se repite 3 veces el precio de 28.8 | T26: =+A26 -> Tradiciones Andinas | U26: =+E26 -> AJINOSIYAO 500ml x 24 | V26: =+H26 -> 28.8 | W26: =_xlfn.CONCAT(A26," ",B26) -> Tradiciones Andinas 11/28/2025 | Z26: =G26*H26 -> 86.4
A27: Tradiciones Andinas | B27: 04/10/2025 | C27: Bill | E27: Arrocito Atomico 150gr x 20 (5.3oz) x 20 | F27: Arrocito Atomico | G27: 2 | H27: 20 | I27: 40 | J27: 6965.64 | K27: =COUNTIF($E$2:$E$1438,E27) -> 2 | L27: =IF(K27>1,_xlfn.CONCAT("Se repite ",K27," veces"),"No se repite") -> Se repite 2 veces | M27: =_xlfn.CONCAT(A27,"-",E27) -> Tradiciones Andinas-Arrocito Atomico 150gr x 20 (5.3oz) x 20 | N27: =COUNTIF($M$2:$M$1438,M27) -> 2 | O27: =IF(N27>1,_xlfn.CONCAT("Se repite ",N27," veces en ",A27),"No se repite en proveedor") -> Se repite 2 veces en Tradiciones Andinas | P27: =_xlfn.CONCAT(A27,"-",E27,"-",H27) -> Tradiciones Andinas-Arrocito Atomico 150gr x 20 (5.3oz) x 20-20 | Q27: =COUNTIF($P$2:$P$1438,P27) -> 1 | R27: =IF(Q27>1,_xlfn.CONCAT("Se repite ",Q27," veces el precio de ",H27),"No se repite") -> No se repite | S27: =_xlfn.CONCAT("El producto ",E27," ",O27,IF(R27="No se repite",_xlfn.CONCAT(" Una vez con el precio ",H27),_xlfn.CONCAT(", ",R27))) -> El producto Arrocito Atomico 150gr x 20 (5.3oz) x 20 Se repite 2 veces en Tradiciones Andinas Una vez con el precio 20 | T27: =+A27 -> Tradiciones Andinas | U27: =+E27 -> Arrocito Atomico 150gr x 20 (5.3oz) x 20 | V27: =+H27 -> 20 | W27: =_xlfn.CONCAT(A27," ",B27) -> Tradiciones Andinas 04/10/2025 | Z27: =G27*H27 -> 40
A28: Tradiciones Andinas | B28: 12/03/2025 | C28: Bill | D28: 493132 | E28: Arrocito Atomico 150gr x 20 (5.3oz) x 20 | F28: TA- PERU - GOLOSINAS - DULCES - Arrocito Atomico- 20 / 150g - CH146 | G28: 2 | H28: 21.4 | I28: 42.8 | J28: 118453.32 | K28: =COUNTIF($E$2:$E$1438,E28) -> 2 | L28: =IF(K28>1,_xlfn.CONCAT("Se repite ",K28," veces"),"No se repite") -> Se repite 2 veces | M28: =_xlfn.CONCAT(A28,"-",E28) -> Tradiciones Andinas-Arrocito Atomico 150gr x 20 (5.3oz) x 20 | N28: =COUNTIF($M$2:$M$1438,M28) -> 2 | O28: =IF(N28>1,_xlfn.CONCAT("Se repite ",N28," veces en ",A28),"No se repite en proveedor") -> Se repite 2 veces en Tradiciones Andinas | P28: =_xlfn.CONCAT(A28,"-",E28,"-",H28) -> Tradiciones Andinas-Arrocito Atomico 150gr x 20 (5.3oz) x 20-21.4 | Q28: =COUNTIF($P$2:$P$1438,P28) -> 1 | R28: =IF(Q28>1,_xlfn.CONCAT("Se repite ",Q28," veces el precio de ",H28),"No se repite") -> No se repite | S28: =_xlfn.CONCAT("El producto ",E28," ",O28,IF(R28="No se repite",_xlfn.CONCAT(" Una vez con el precio ",H28),_xlfn.CONCAT(", ",R28))) -> El producto Arrocito Atomico 150gr x 20 (5.3oz) x 20 Se repite 2 veces en Tradiciones Andinas Una vez con el precio 21.4 | T28: =+A28 -> Tradiciones Andinas | U28: =+E28 -> Arrocito Atomico 150gr x 20 (5.3oz) x 20 | V28: =+H28 -> 21.4 | W28: =_xlfn.CONCAT(A28," ",B28) -> Tradiciones Andinas 12/03/2025 | Z28: =G28*H28 -> 42.8
A29: Peru Chef | B29: 03/26/2025 | C29: Bill | E29: Atun Florida Solido en aceite 6 oz X 48 | F29: Atun Florida 6 Oz X 48 | G29: 1 | H29: 82.5 | I29: 82.5 | J29: 885.8 | K29: =COUNTIF($E$2:$E$1438,E29) -> 6 | L29: =IF(K29>1,_xlfn.CONCAT("Se repite ",K29," veces"),"No se repite") -> Se repite 6 veces | M29: =_xlfn.CONCAT(A29,"-",E29) -> Peru Chef-Atun Florida Solido en aceite 6 oz X 48 | N29: =COUNTIF($M$2:$M$1438,M29) -> 6 | O29: =IF(N29>1,_xlfn.CONCAT("Se repite ",N29," veces en ",A29),"No se repite en proveedor") -> Se repite 6 veces en Peru Chef | P29: =_xlfn.CONCAT(A29,"-",E29,"-",H29) -> Peru Chef-Atun Florida Solido en aceite 6 oz X 48-82.5 | Q29: =COUNTIF($P$2:$P$1438,P29) -> 2 | R29: =IF(Q29>1,_xlfn.CONCAT("Se repite ",Q29," veces el precio de ",H29),"No se repite") -> Se repite 2 veces el precio de 82.5 | S29: =_xlfn.CONCAT("El producto ",E29," ",O29,IF(R29="No se repite",_xlfn.CONCAT(" Una vez con el precio ",H29),_xlfn.CONCAT(", ",R29))) -> El producto Atun Florida Solido en aceite 6 oz X 48 Se repite 6 veces en Peru Chef, Se repite 2 veces el precio de 82.5 | T29: =+A29 -> Peru Chef | U29: =+E29 -> Atun Florida Solido en aceite 6 oz X 48 | V29: =+H29 -> 82.5 | W29: =_xlfn.CONCAT(A29," ",B29) -> Peru Chef 03/26/2025 | Z29: =G29*H29 -> 82.5
A30: Peru Chef | B30: 04/10/2025 | C30: Bill | D30: 55130 | E30: Atun Florida Solido en aceite 6 oz X 48 | F30: Atun Florida Solido en aceite 6 Oz X 48 | G30: 1 | H30: 82.5 | I30: 82.5 | J30: 3132 | K30: =COUNTIF($E$2:$E$1438,E30) -> 6 | L30: =IF(K30>1,_xlfn.CONCAT("Se repite ",K30," veces"),"No se repite") -> Se repite 6 veces | M30: =_xlfn.CONCAT(A30,"-",E30) -> Peru Chef-Atun Florida Solido en aceite 6 oz X 48 | N30: =COUNTIF($M$2:$M$1438,M30) -> 6 | O30: =IF(N30>1,_xlfn.CONCAT("Se repite ",N30," veces en ",A30),"No se repite en proveedor") -> Se repite 6 veces en Peru Chef | P30: =_xlfn.CONCAT(A30,"-",E30,"-",H30) -> Peru Chef-Atun Florida Solido en aceite 6 oz X 48-82.5 | Q30: =COUNTIF($P$2:$P$1438,P30) -> 2 | R30: =IF(Q30>1,_xlfn.CONCAT("Se repite ",Q30," veces el precio de ",H30),"No se repite") -> Se repite 2 veces el precio de 82.5 | S30: =_xlfn.CONCAT("El producto ",E30," ",O30,IF(R30="No se repite",_xlfn.CONCAT(" Una vez con el precio ",H30),_xlfn.CONCAT(", ",R30))) -> El producto Atun Florida Solido en aceite 6 oz X 48 Se repite 6 veces en Peru Chef, Se repite 2 veces el precio de 82.5 | T30: =+A30 -> Peru Chef | U30: =+E30 -> Atun Florida Solido en aceite 6 oz X 48 | V30: =+H30 -> 82.5 | W30: =_xlfn.CONCAT(A30," ",B30) -> Peru Chef 04/10/2025 | Z30: =G30*H30 -> 82.5
